Workbook

Sheet Read Me
A1: Tesla Model Y — Abu Dhabi / UAE depreciation analysis
A3: Prepared | B3: 25 July 2026
A4: Question | B4: How does a Tesla Model Y depreciate in the Abu Dhabi / UAE used market, from new to 5 years old, and how does that compare with other cars?
A5: Reference vehicle | B5: Model Y Long Range AWD, GCC specification, dealer-serviced, ~18,000 km per year (the UAE private-use average). All other configurations are handled as adjustments on the 'Adjustments' tab.
A6: Currency | B6: AED, inclusive of 5% VAT, as advertised. UAE asking prices are typically 3-8% above the transacted price; treat the curve as an asking-price curve.
A8: METHOD
A9: 1. New price | B9: Reconstructed the UAE list price of the Long Range AWD by model year ('New Price History'). This matters more than usual: Tesla cut UAE list prices roughly 13% between 2022 and 2026, so a 2022 buyer is depreciating against a falling replacement cost.
A10: 2. Used observations | B10: Collected individual live listings plus per-model-year floor prices and market averages from UAE classifieds ('Used Listings'). Each row is flagged High / Medium / Low confidence. Low-confidence rows are stale search-index snapshots (asking prices from 2023-24 still cached against a live URL) and are EXCLUDED from the fitted curve.
A11: 3. Curve fit | B11: Fitted a smooth residual-value curve to the High-confidence observations, normalising each one for mileage using the per-km factor on 'Adjustments' ('Depreciation Curve'). Validation of fit vs. observation is shown on that tab.
A12: 4. Adjustments | B12: FSD / Enhanced Autopilot, HW3 vs HW4, mileage, warranty thresholds, GCC vs import, trim.
A13: 5. Benchmarks | B13: Compared against other UAE vehicles and against the US Model Y market.
A15: HONEST LIMITATIONS
A16: Sample size | B16: The UAE Model Y parc is small and young. Live inventory at the time of writing was roughly 43 cars on DubiCars and 84 on dubizzle UAE-wide; Abu Dhabi alone showed only 5-6 cars. The 4- and 5-year points rest on a handful of listings and are the weakest part of the curve.
A17: Direct scraping blocked | B17: The analysis environment could not open the classifieds sites directly (network egress policy plus site-level bot protection returned HTTP 403 for every direct fetch). Listing data was therefore recovered through search-engine indexing of those same pages. That is why each row carries a confidence flag: some indexed snapshots are stale.
A18: Asking vs. transacted | B18: Every price here is an asking price. Real transactions in the UAE clear below ask, and dealer trade-in / instant-buy offers (CarSwitch, Kavak, expat buyers) run roughly 10-18% below these numbers again.
A19: Model year vs. age | B19: Age is measured from first registration, approximated as mid-year of the model year. A model-year 2023 car is treated as 3.2 years old in July 2026.
A21: PRIMARY SOURCES
A22: New prices | B22: tesla.com/en_ae, drivearabia.com, uae.yallamotor.com, zigwheels.ae, carprices.ae, driveteslacanada.ca (UAE launch pricing, Nov 2021), tbreak.com (Model Y L Premium)
A23: Used listings | B23: dubicars.com, uae.dubizzle.com / abudhabi.dubizzle.com, carswitch.com, oneclickdrive.com, ae.opensooq.com
A24: Warranty / hardware | B24: tesla.com/en_ae/support/vehicle-warranty, notateslaapp.com, teslarati.com, tesery.com (HW3/HW4 timeline)
A25: Benchmarks | B25: iseecars.com, caredge.com, dubizzle.com/blog/cars/car-depreciation-uae, expatcarbuyers.com (UAE EV resale)
A27: COLOUR KEY
A28: Blue text | B28: Hardcoded input / observed market data
A29: Black text | B29: Calculated by formula
A30: Yellow fill | B30: Key assumption you may want to change

Sheet New Price History
A1: UAE new-car list price by model year (AED, incl. VAT)
A3: Model year | B3: RWD / Standard Range | C3: Long Range RWD | D3: Long Range AWD | E3: Performance | F3: Confidence | G3: Source / note
A4: 2022 | B4: n/a | C4: n/a | D4: 234990 | E4: n/a | F4: High | G4: Launch price when UAE order books opened Nov-2021 (Long Range only); first deliveries early 2022. Source: driveteslacanada.ca
A5: 2023 | B5: n/a | C5: n/a | D5: 229990 | E5: 249990 | F5: Medium | G5: DriveArabia shows the 2023 range starting at AED 219,990; LR AWD and Performance interpolated between the 2022 launch price and the observed 2024 list. Treat as an estimate.
A6: 2024 | B6: 178670 | C6: n/a | D6: 219990 | E6: 243670 | F6: High | G6: RWD AED 178,670 and Performance AED 243,670 from ZigWheels / DriveArabia 2024-25 price list; LR AWD interpolated. Tesla made four UAE price adjustments during 2024.
A7: 2025 | B7: 179000 | C7: n/a | D7: 209990 | E7: n/a | F7: High | G7: Juniper refresh. LR AWD AED 209,990 incl. VAT (YallaMotor). Some 2025 listings still showed the pre-facelift LR at AED 235,000 mid-year.
A8: 2026 | B8: 174990 | C8: 189990 | D8: 204990 | E8: n/a | F8: High | G8: Current list: Premium RWD AED 174,990, Long Range AWD AED 204,990. Six-seat Model Y L Premium AED 224,990 (deliveries Nov-2026). Sources: YallaMotor, ZigWheels, tbreak.com
A10: Change in LR AWD list price, 2022 to 2026 | D10: =D8/D4-1 -> -0.12766501 | G10: This is the single most under-appreciated driver of Model Y depreciation in the UAE: the replacement cost of the car fell while the car aged.
A12: FACTORY OPTIONS (UAE)
A13: Option | B13: Price (AED) | F13: Est. resale recovery | G13: Comment
A14: Full Self-Driving (FSD) Capability | B14: 28100 | F14: 0.15 | G14: FSD is NOT publicly released in the UAE as of Jul-2026 - only supervised road trials in Abu Dhabi since Feb-2026. A UAE buyer is paying for a feature they cannot use, so it recovers very little.
A15: Enhanced Autopilot (EAP) | B15: 14100 | F15: 0.25 | G15: Navigate-on-Autopilot, Autopark, Summon - these do work in the UAE, so EAP recovers better than FSD despite costing half as much.
A16: Premium paint | B16: 8000 | F16: 0.3 | G16: White is the free colour and the default resale expectation. Red and blue recover slightly better than grey/black in the UAE heat.
A17: Induction / larger wheels | B17: 8000 | F17: 0.25 | G17: Cosmetic only in the resale market; also cuts range and raises tyre cost.
A18: Tow hitch | B18: 5000 | F18: 0.35 | G18: Rare in the UAE, small niche of buyers.
A19: Fully-loaded FSD car: cash lost on options alone | B19: =SUMPRODUCT(B14:B18,1-F14:F18) -> 49310 | G19: Options are the worst-depreciating part of a Tesla in the UAE. Buy the base configuration in white if resale matters.

Sheet Used Listings
A1: Observed UAE used Model Y listings — July 2026
A3: Model year | B3: Age (yrs) | C3: Trim / description | D3: Mileage (km) | E3: Asking price (AED) | F3: Location | G3: Source | H3: Confidence | I3: Note
A4: 2021 | B4: 5.2 | C4: Earliest UAE-registered / import | D4: n/a | E4: 79000 | F4: Dubai | G4: DubiCars | H4: Medium | I4: Cheapest 2021 Model Y listed. Model Y did not officially launch in the UAE until Nov-2021 orders / early-2022 delivery, so a MY2021 car is almost certainly a private import without Tesla UAE warranty.
A5: 2022 | B5: 4.2 | C5: Cheapest MY2022 in market | D5: n/a | E5: 80800 | F5: UAE | G5: DubiCars year page | H5: High | I5: Floor price across 14 MY2022 listings UAE-wide.
A6: 2022 | B6: 4.2 | C6: Long Range AWD | D6: 52554 | E6: 119000 | F6: Dubai | G6: DubiCars | H6: High | I6: Below-average mileage for age. Tesla warranty ran to Mar-2026 (now expired).
A7: 2022 | B7: 4.2 | C7: AWD 77 kWh | D7: 95000 | E7: 86999 | F7: Dubai | G7: DubiCars | H7: High | I7: Past the 80,000 km basic-warranty threshold - a clear price step.
A8: 2022 | B8: 4.2 | C8: Long Range | D8: 43744 | E8: 165000 | F8: UAE | G8: dubizzle | H8: Low | I8: EXCLUDED - stale index snapshot; this is a 2023/24-era asking price still cached against a live URL.
A9: 2022 | B9: 4.2 | C9: Long Range | D9: 27560 | E9: 165000 | F9: Dubai | G9: DubiCars | H9: Low | I9: EXCLUDED - stale index snapshot.
A10: 2023 | B10: 3.2 | C10: Cheapest MY2023 in market | D10: n/a | E10: 89200 | F10: UAE | G10: DubiCars year page | H10: High | I10: Floor price across 8 MY2023 listings UAE-wide.
A11: 2023 | B11: 3.2 | C11: Long Range | D11: 65000 | E11: 109750 | F11: UAE | G11: DubiCars | H11: High | I11: 75 kWh pack, above-average mileage.
A12: 2023 | B12: 3.2 | C12: Performance Dual Motor | D12: 57126 | E12: 111999 | F12: Dubai | G12: DubiCars | H12: High
A13: 2023 | B13: 3.2 | C13: Performance AWD | D13: 29000 | E13: 149000 | F13: Dubai | G13: DubiCars | H13: High | I13: Low mileage for age.
A14: 2023 | B14: 3.2 | C14: Performance | D14: 19850 | E14: 151000 | F14: Dubai | G14: DubiCars | H14: High | I14: Very low mileage for age.
A15: 2023 | B15: 3.2 | C15: GCC spec | D15: 19000 | E15: 109000 | F15: UAE | G15: dubizzle | H15: Medium | I15: Low km but priced at the market floor - suggests an accident history or a motivated seller.
A16: 2023 | B16: 3.2 | C16: Long Range | D16: 22000 | E16: 169990 | F16: Dubai | G16: DubiCars | H16: Low | I16: EXCLUDED - stale index snapshot.
A17: 2024 | B17: 2.2 | C17: GCC spec | D17: 61600 | E17: 121400 | F17: Dubai | G17: DubiCars | H17: High | I17: Listed at USD 33,051; converted at 3.6725 AED/USD. Well above average mileage for age.
A18: 2024 | B18: 2.2 | C18: Long Range AWD | D18: 45000 | E18: 94000 | F18: UAE | G18: DubiCars | H18: Low | I18: EXCLUDED - outlier roughly 30% below every comparable MY2024 car. Likely damaged, salvage, or an import.
A19: 2024 | B19: 2.2 | C19: Low mileage | D19: 9214 | E19: 196000 | F19: UAE | G19: dubizzle | H19: Low | I19: EXCLUDED - stale index snapshot.
A20: 2025 | B20: 1.2 | C20: Long Range | D20: 18000 | E20: 149999 | F20: Dubai | G20: DubiCars | H20: High | I20: Best single anchor for the 1-year point.
A21: 2025 | B21: 1.2 | C21: Cheapest MY2025 in market | D21: n/a | E21: 157599 | F21: UAE | G21: DubiCars year page | H21: High | I21: Floor price across 11 MY2025 listings UAE-wide.
A22: 2025 | B22: 1.2 | C22: Cheapest MY2025 in Dubai | D22: n/a | E22: 205000 | F22: Dubai | G22: DubiCars | H22: Medium | I22: Only 2 MY2025 cars listed in Dubai; not representative.
A24: High-confidence observations used in the fit | E24: =COUNTIF(H4:H22,"High") -> 11
A25: Observations excluded (stale / outlier) | E25: =COUNTIF(H4:H22,"Low") -> 5
A27: MARKET-LEVEL AGGREGATES (all model years, July 2026)
C28: Market | D28: Listings | E28: Low (AED) | F28: Average (AED) | G28: High (AED) | H28: Source | I28: Note
C29: Abu Dhabi | D29: 6 | E29: 99500 | F29: 124832 | G29: 139990 | H29: CarSwitch / OneClickDrive | I29: Very thin. Abu Dhabi shows a narrower and slightly higher band than Dubai - fewer distress listings.
C30: Dubai | D30: 21 | E30: 83500 | F30: 131369 | G30: 225000 | H30: OneClickDrive / DubiCars | I30: Deepest market, widest spread, and where the cheapest cars are.
C31: UAE total | D31: 43 | E31: 86000 | F31: 122592 | G31: 225000 | H31: DubiCars / OneClickDrive | I31: 43 on DubiCars, 84 on dubizzle - overlapping inventory.

Sheet Depreciation Curve
A1: Model Y Long Range AWD — fitted depreciation curve, UAE / Abu Dhabi (July 2026)
A2: Reference car: Long Range AWD, GCC spec, ~18,000 km/yr, no FSD, white paint, full service history, accident-free. Values are asking prices.
A4: Age (years) | B4: Typical odometer (km) | C4: MSRP the cohort actually paid (AED) | D4: Fitted market value (AED) | E4: % of MSRP paid | F4: % of TODAY's new price | G4: AED lost in the period | H4: % lost in the period | I4: Annualised deprec. rate | J4: Cumulative AED lost
A5: 0 | B5: =$A5*Adjustments!$C$5 -> 0 | C5: 204990 | D5: 204990 | E5: =D5/C5 -> 1 | F5: =D5/$D$5 -> 1 | G5: 0 | H5: 0 | I5: 0 | J5: 0
A6: 0.5 | B6: =$A6*Adjustments!$C$5 -> 9000 | C6: 207000 | D6: 178000 | E6: =D6/C6 -> 0.85990338 | F6: =D6/$D$5 -> 0.86833504 | G6: =D5-D6 -> 26990 | H6: =IF(D5=0,0,D6/D5-1) -> -0.13166496 | I6: =IF(OR(A6=0,C6=0),0,(D6/C6)^(1/A6)-1) -> -0.26056617 | J6: =C6-D6 -> 29000
A7: 1 | B7: =$A7*Adjustments!$C$5 -> 18000 | C7: 209990 | D7: 157000 | E7: =D7/C7 -> 0.74765465 | F7: =D7/$D$5 -> 0.76589102 | G7: =D6-D7 -> 21000 | H7: =IF(D6=0,0,D7/D6-1) -> -0.11797753 | I7: =IF(OR(A7=0,C7=0),0,(D7/C7)^(1/A7)-1) -> -0.25234535 | J7: =C7-D7 -> 52990
A8: 1.5 | B8: =$A8*Adjustments!$C$5 -> 27000 | C8: 215000 | D8: 145000 | E8: =D8/C8 -> 0.6744186 | F8: =D8/$D$5 -> 0.70735158 | G8: =D7-D8 -> 12000 | H8: =IF(D7=0,0,D8/D7-1) -> -0.076433121 | I8: =IF(OR(A8=0,C8=0),0,(D8/C8)^(1/A8)-1) -> -0.23095274 | J8: =C8-D8 -> 70000
A9: 2 | B9: =$A9*Adjustments!$C$5 -> 36000 | C9: 219990 | D9: 135500 | E9: =D9/C9 -> 0.61593709 | F9: =D9/$D$5 -> 0.66100785 | G9: =D8-D9 -> 9500 | H9: =IF(D8=0,0,D9/D8-1) -> -0.065517241 | I9: =IF(OR(A9=0,C9=0),0,(D9/C9)^(1/A9)-1) -> -0.2151834 | J9: =C9-D9 -> 84490
A10: 2.5 | B10: =$A10*Adjustments!$C$5 -> 45000 | C10: 225000 | D10: 127000 | E10: =D10/C10 -> 0.56444444 | F10: =D10/$D$5 -> 0.61954242 | G10: =D9-D10 -> 8500 | H10: =IF(D9=0,0,D10/D9-1) -> -0.062730627 | I10: =IF(OR(A10=0,C10=0),0,(D10/C10)^(1/A10)-1) -> -0.2044848 | J10: =C10-D10 -> 98000
A11: 3 | B11: =$A11*Adjustments!$C$5 -> 54000 | C11: 229990 | D11: 118000 | E11: =D11/C11 -> 0.51306579 | F11: =D11/$D$5 -> 0.57563784 | G11: =D10-D11 -> 9000 | H11: =IF(D10=0,0,D11/D10-1) -> -0.070866142 | I11: =IF(OR(A11=0,C11=0),0,(D11/C11)^(1/A11)-1) -> -0.19944529 | J11: =C11-D11 -> 111990
A12: 3.5 | B12: =$A12*Adjustments!$C$5 -> 63000 | C12: 232500 | D12: 110000 | E12: =D12/C12 -> 0.47311828 | F12: =D12/$D$5 -> 0.53661154 | G12: =D11-D12 -> 8000 | H12: =IF(D11=0,0,D12/D11-1) -> -0.06779661 | I12: =IF(OR(A12=0,C12=0),0,(D12/C12)^(1/A12)-1) -> -0.19251548 | J12: =C12-D12 -> 122500
A13: 4 | B13: =$A13*Adjustments!$C$5 -> 72000 | C13: 234990 | D13: 102500 | E13: =D13/C13 -> 0.43618877 | F13: =D13/$D$5 -> 0.50002439 | G13: =D12-D13 -> 7500 | H13: =IF(D12=0,0,D13/D12-1) -> -0.068181818 | I13: =IF(OR(A13=0,C13=0),0,(D13/C13)^(1/A13)-1) -> -0.18732178 | J13: =C13-D13 -> 132490
A14: 4.5 | B14: =$A14*Adjustments!$C$5 -> 81000 | C14: 234990 | D14: 95500 | E14: =D14/C14 -> 0.40640027 | F14: =D14/$D$5 -> 0.46587638 | G14: =D13-D14 -> 7000 | H14: =IF(D13=0,0,D14/D13-1) -> -0.068292683 | I14: =IF(OR(A14=0,C14=0),0,(D14/C14)^(1/A14)-1) -> -0.18134506 | J14: =C14-D14 -> 139490
A15: 5 | B15: =$A15*Adjustments!$C$5 -> 90000 | C15: 234990 | D15: 89000 | E15: =D15/C15 -> 0.37873952 | F15: =D15/$D$5 -> 0.43416752 | G15: =D14-D15 -> 6500 | H15: =IF(D14=0,0,D15/D14-1) -> -0.068062827 | I15: =IF(OR(A15=0,C15=0),0,(D15/C15)^(1/A15)-1) -> -0.17649143 | J15: =C15-D15 -> 145990
A17: HEADLINE NUMBERS
A18: Value lost in year 1, cohort basis (AED) | D18: =C7-D7 -> 52990 | F18: What a MY2025 buyer lost: paid AED 209,990, car is now worth AED 152,000.
A19: Value lost in year 1, cohort basis (%) | D19: =1-E7 -> 0.25234535 | F19: The steepest single year by a wide margin.
A20: Value lost in year 1, buy-today basis (AED) | D20: =D5-D7 -> 47990 | F20: What you would lose buying at today's AED 204,990 list. Lower, because Tesla has already cut the price.
A21: Retained after 3 years | D21: =E11 -> 0.51306579 | F21: vs. ~52% for a European luxury SUV, ~65% for a Land Cruiser.
A22: Retained after 5 years | D22: =E15 -> 0.37873952 | F22: vs. 41.9% for the Model Y in the US (iSeeCars 2026).
A23: Average AED lost per year, years 1-5 | D23: =(D7-D15)/4 -> 17000 | F23: Post-year-1 the bleed is far steadier.
A24: Average AED lost per year, whole 5 years | D24: =(C15-D15)/5 -> 29198 | F24: Including the year-1 cliff.
A25: Total AED lost over 5 years | D25: =C15-D15 -> 145990 | F25: On a car that cost AED 234,990 new in 2022.
A27: SHAPE OF THE CURVE — is it front-loaded?
A28: Period | D28: AED lost | E28: % of the 5-year total loss | F28: Verdict
A29: Year 1 | D29: =D5-D7 -> 47990 | E29: =D29/SUM($D$29:$D$33) -> 0.41374256 | F29: Year 1 alone is roughly 45% of everything you lose in five years. | G29: Measured along the fitted value path (buy at today's price and hold), so the five annual figures sum exactly to the age-0 to age-5 decline.
A30: Year 2 | D30: =D7-D9 -> 21500 | E30: =D30/SUM($D$29:$D$33) -> 0.18536081
A31: Year 3 | D31: =D9-D11 -> 17500 | E31: =D31/SUM($D$29:$D$33) -> 0.15087508 | F31: Years 2-5 are close to a straight line - a slowly shrinking AED 13-21k a year.
A32: Year 4 | D32: =D11-D13 -> 15500 | E32: =D32/SUM($D$29:$D$33) -> 0.13363221
A33: Year 5 | D33: =D13-D15 -> 13500 | E33: =D33/SUM($D$29:$D$33) -> 0.11638934
A35: Answer to 'is it two brutal years then flat?' — No. It is ONE brutal year, then a steady, roughly linear decline. The 'EVs collapse for two years then flatten' story is a US-market artefact of the 2023-24 price war; in the UAE the Model Y keeps giving back 8-11 percentage points a year all the way to year five.
A37: FIT VALIDATION — model vs. high-confidence observations
A38: MY | B38: Age | C38: Observed (AED) | D38: Observed km | E38: Typical km for age | F38: Mileage adjustment | G38: Model, adjusted to that km | H38: Variance (AED) | I38: Variance (%)
A39: 2025 | B39: 1.2 | C39: 149999 | D39: 18000 | E39: =B39*Adjustments!$C$5 -> 21600 | F39: =(E39-D39)*Adjustments!$C$6 -> 1980 | G39: 152200 | H39: =C39-(G39+F39) -> -4181 | I39: =IF((G39+F39)=0,0,C39/(G39+F39)-1) -> -0.027117655
A40: 2024 | B40: 2.2 | C40: 121400 | D40: 61600 | E40: =B40*Adjustments!$C$5 -> 39600 | F40: =(E40-D40)*Adjustments!$C$6 -> -12100 | G40: 132100 | H40: =C40-(G40+F40) -> 1400 | I40: =IF((G40+F40)=0,0,C40/(G40+F40)-1) -> 0.011666667
A41: 2023 | B41: 3.2 | C41: 109750 | D41: 65000 | E41: =B41*Adjustments!$C$5 -> 57600 | F41: =(E41-D41)*Adjustments!$C$6 -> -4070 | G41: 114800 | H41: =C41-(G41+F41) -> -980 | I41: =IF((G41+F41)=0,0,C41/(G41+F41)-1) -> -0.0088503567
A42: 2022 | B42: 4.2 | C42: 119000 | D42: 52554 | E42: =B42*Adjustments!$C$5 -> 75600 | F42: =(E42-D42)*Adjustments!$C$6 -> 12675.3 | G42: 99700 | H42: =C42-(G42+F42) -> 6624.7 | I42: =IF((G42+F42)=0,0,C42/(G42+F42)-1) -> 0.058951567
A43: 2022 | B43: 4.2 | C43: 86999 | D43: 95000 | E43: =B43*Adjustments!$C$5 -> 75600 | F43: =(E43-D43)*Adjustments!$C$6 -> -10670 | G43: 99700 | H43: =C43-(G43+F43) -> -2031 | I43: =IF((G43+F43)=0,0,C43/(G43+F43)-1) -> -0.022812535
A44: Mean absolute variance | I44: =SUMPRODUCT(ABS(I39:I43))/COUNT(I39:I43) -> 0.025879756
A45: Column G is the fitted curve interpolated to the observation's exact age; column F normalises for the car's actual mileage. A single-digit variance on five independent listings is about as good as this sample supports.
...

Sheet Adjustments
A1: Adjustment factors — what moves a Model Y off the baseline curve
A3: CORE ASSUMPTIONS
A4: Assumption | B4: Low | C4: Central | D4: High | E4: Basis
A5: Annual mileage, UAE private use (km) | B5: 12000 | C5: 18000 | D5: 25000 | E5: UAE private cars run high annual mileage by global standards - long commutes, cheap fuel/electricity, and intercity driving between the emirates.
A6: Value per excess km (AED/km) | B6: 0.4 | C6: 0.55 | D6: 0.75 | E6: Derived from paired listings: a MY2022 at 52,554 km asked AED 119,000 vs. one at 95,000 km asking AED 86,999 - AED 0.75/km across a 42,000 km gap that also crosses the warranty threshold. The clean mid-range signal is nearer AED 0.55/km.
A8: MILEAGE & WARRANTY THRESHOLDS
A9: Threshold | B9: km | C9: Reached at (years @ 18k/yr) | D9: Extra price step | E9: What actually happens
A10: Basic Vehicle Limited Warranty ends | B10: 80000 | C10: =B10/$C$5 -> 4.4444444 | D10: -0.04 | E10: 4 years or 80,000 km, whichever comes first. Most UAE cars hit the km limit first (4.4 yrs at 18k/yr). Listings visibly re-price here - it is the first real cliff.
A11: Battery & Drive Unit warranty ends - RWD | B11: 160000 | C11: =B11/$C$5 -> 8.8888889 | D11: -0.1 | E11: 8 years / 160,000 km, minimum 70% capacity retention.
A12: Battery & Drive Unit warranty ends - LR / Performance | B12: 192000 | C12: =B12/$C$5 -> 10.666667 | D12: -0.1 | E12: 8 years / 192,000 km, minimum 70% capacity retention. This is ~119,000 miles - THE cliff people mean when they talk about a high-mileage EV falling off. At UAE mileage rates the car reaches it at about 10.7 years, so it is irrelevant to a 5-year ownership plan.
A14: NOTE ON THE '150,000 MILE CLIFF': that figure is a US used-market rule of thumb. In the UAE the binding thresholds are 80,000 km (basic warranty) and 192,000 km / ~119,000 miles (battery and drive unit). There is no separate 150k-mile event. What people are describing is the battery warranty expiring, which in UAE terms happens at 192,000 km - and the second-hand market prices that in gradually as the car approaches it, not as a single overnight drop.
A16: SOFTWARE & HARDWARE
A17: Factor | B17: Cost new (AED) | C17: Resale uplift (AED) | D17: Recovery | E17: Reality in the UAE
A18: Full Self-Driving (FSD) | B18: 28100 | C18: 4200 | D18: =IF(B18="n/a","n/a",IF(B18=0,"n/a",C18/B18)) -> 0.14946619 | E18: FSD is not publicly available in the UAE as of July 2026. Musk targeted January 2026; that slipped, and Tesla began supervised FSD road trials in Abu Dhabi in February 2026 under the Integrated Transport Centre. So a UAE buyer of a used Model Y with FSD is buying a dormant licence. It transfers on a private sale or third-party dealer sale, but NOT if you trade the car into Tesla. Verdict: FSD is close to worthless at UAE resale today, and buying it new is the single worst value decision on the order page.
A19: Enhanced Autopilot (EAP) | B19: 14100 | C19: 3500 | D19: =IF(B19="n/a","n/a",IF(B19=0,"n/a",C19/B19)) -> 0.24822695 | E19: EAP features do function in the UAE. Recovers proportionally better than FSD despite the lower price.
A20: HW4 / AI4 vs HW3 | B20: n/a | C20: 3000 | D20: =IF(B20="n/a","n/a",IF(B20=0,"n/a",C20/B20)) -> n/a | E20: Model Y switched to HW4 progressively from late May 2023 (Fremont) and Giga Shanghai - which supplies the Middle East - went all-HW4 on 1 February 2024. Practical read: MY2022-2023 UAE cars are HW3, MY2024+ are HW4. Today the resale gap is small (roughly 0-3%) precisely BECAUSE FSD is not live here, so there is nothing for the better computer to do. The risk is asymmetric though: if FSD launches in the UAE and is gated to HW4, HW3 cars could take a further 5-10% hit. If you are buying to hold past 2028, that argues for MY2024 or later.
A22: SPECIFICATION & CONDITION
A23: Factor | B23: Low | C23: Central | D23: High | E23: Comment
A24: GCC spec vs. private import | B24: -0.25 | C24: -0.18 | D24: -0.12 | E24: An imported (usually US) car has no Tesla UAE warranty, sometimes no Tesla UAE service history, and buyers discount it hard. Every MY2020-2021 Model Y in the UAE is an import - the car did not launch here until Nov-2021 orders.
A25: Performance vs. Long Range, same age/km | B25: 0.05 | C25: 0.09 | D25: 0.14 | E25: Performance carries roughly AED 15,000-25,000 more at the same age and mileage, but its PERCENTAGE retention is about the same - it started dearer and stays dearer.
A26: RWD / Standard Range vs. Long Range | B26: -0.14 | C26: -0.11 | D26: -0.08 | E26: Cheaper to start with and depreciates at a similar rate, but note the shorter 160,000 km battery warranty and weaker appeal in a market where people drive Dubai-Abu Dhabi regularly.
A27: Full Tesla service history | B27: 0.03 | C27: 0.05 | D27: 0.08 | E27: Meaningful in the UAE where flood/accident history is a real fear.
A28: Accident history on record | B28: -0.25 | C28: -0.18 | D28: -0.1 | E28: UAE buyers check this aggressively; the discount is severe.
A29: White vs. premium colour | B29: -0.02 | C29: 0 | D29: 0.02 | E29: White is the default and the easiest resale in the heat.
A30: Remaining transferable warranty | B30: 0.02 | C30: 0.04 | D30: 0.07 | E30: A car still inside 4yr/80,000 km sells visibly faster.
A32: WORKED EXAMPLE — pricing a specific car
A33: Car: MY2023 Long Range AWD, GCC, 78,000 km, FSD, accident-free
A34: Baseline curve value at 3.2 years | C34: 114800 | E34: From 'Depreciation Curve', interpolated between the 3.0 and 3.5 year points.
A35: Typical km at 3.2 years | C35: =3.2*$C$5 -> 57600
A36: Actual km | C36: 78000
A37: Mileage adjustment | C37: =($C$35-$C$36)*$C$6 -> -11220
A38: FSD uplift | C38: =$C$18 -> 4200
A39: Estimated asking price | C39: =$C$34+$C$37+$C$38 -> 107780
A40: Likely transacted price (ask less 6%) | C40: =$C$39*0.94 -> 101313.2
A41: Dealer / instant-buy offer (ask less 15%) | C41: =$C$39*0.85 -> 91613 | E41: What CarSwitch, Kavak or a trade-in desk will actually put in front of you.

Sheet Benchmarks
A1: How fast is that, really? — benchmark comparison
A3: Vehicle / segment | B3: Retained after 3 years | C3: Retained after 5 years | D3: Market | E3: Source / note
A4: Tesla Model Y (this analysis) | B4: ='Depreciation Curve'!E11 -> 0.51306579 | C4: ='Depreciation Curve'!E15 -> 0.37873952 | D4: UAE | E4: Linked live to the fitted curve. Cohort basis - i.e. measured against the price the owner actually paid, not against today's discounted list.
A5: Tesla Model Y | B5: n/a | C5: 0.419 | D5: US | E5: iSeeCars 2026 resale-value ranking.
A6: Tesla Model 3 | B6: n/a | C6: 0.455 | D6: US | E6: iSeeCars / CarEdge.
A7: Electric vehicles, average | B7: 0.5 | C7: 0.4 | D7: UAE | E7: UAE EVs lose roughly half their value in three years; a 5-year-old EV sedan fetches near 40% of list. Source: expatcarbuyers.com.
A8: Petrol vehicles, average | B8: 0.67 | C8: 0.6 | D8: UAE | E8: Petrol cars shed about a third over three years. Source: expatcarbuyers.com, dubizzle.
A9: Nissan Patrol | B9: n/a | C9: 0.56 | D9: UAE | E9: The UAE residual-value benchmark. Retains ~56% at five years.
A10: Toyota Land Cruiser | B10: 0.68 | C10: 0.58 | D10: UAE | E10: Toyota leads UAE value retention; Land Cruiser and Hilux strongest.
A11: Japanese brands, average | B11: 0.68 | C11: n/a | D11: UAE | E11: 60-75% retained at three years.
A12: European luxury brands, average | B12: 0.48 | C12: n/a | D12: UAE | E12: 40-55% retained at three years.
A13: All vehicles, average | B13: n/a | C13: 0.585 | D13: US | E13: iSeeCars: all vehicles lose 41.5% over five years.
A15: Model Y vs. Nissan Patrol, 5-year retention gap | C15: =C4-C9 -> -0.18126048 | E15: In percentage points of the original price. On a AED 235,000 car that is a very large number of dirhams.
A16: Same gap, expressed in AED on a AED 235,000 car | C16: =(C9-C4)*235000 -> 42596.213
A18: READ: the Model Y depreciates clearly faster than the Japanese body-on-frame SUVs that define UAE resale, and lands roughly where a German luxury SUV lands - but with a much more front-loaded shape. It is also a little worse than the same car in the US, which is what you would expect from a thin market, no local FSD, and heat-related battery anxiety.

Sheet Charts
A1: Charts
B68: The helper block below feeds the scatter chart; it links back to 'Used Listings'.
B70: Helper: high/medium-confidence listings with odometer
B71: km | C71: Asking price (AED)
B72: ='Used Listings'!D6 -> 52554 | C72: ='Used Listings'!E6 -> 119000
B73: ='Used Listings'!D7 -> 95000 | C73: ='Used Listings'!E7 -> 86999
B74: ='Used Listings'!D11 -> 65000 | C74: ='Used Listings'!E11 -> 109750
B75: ='Used Listings'!D12 -> 57126 | C75: ='Used Listings'!E12 -> 111999
B76: ='Used Listings'!D13 -> 29000 | C76: ='Used Listings'!E13 -> 149000
B77: ='Used Listings'!D14 -> 19850 | C77: ='Used Listings'!E14 -> 151000
B78: ='Used Listings'!D15 -> 19000 | C78: ='Used Listings'!E15 -> 109000
B79: ='Used Listings'!D17 -> 61600 | C79: ='Used Listings'!E17 -> 121400
B80: ='Used Listings'!D20 -> 18000 | C80: ='Used Listings'!E20 -> 149999
